<?xml version="1.0" encoding="UTF-8"?>
<testng-results skipped="0" failed="1" ignored="0" total="1" passed="0">
  <reporter-output>
  </reporter-output>
  <suite name="Default suite" duration-ms="15087" started-at="2018-01-10T11:58:53Z" finished-at="2018-01-10T11:59:08Z">
    <groups>
    </groups>
    <test name="Default test" duration-ms="15087" started-at="2018-01-10T11:58:53Z" finished-at="2018-01-10T11:59:08Z">
      <class name="Extent_Report.TestReport2">
        <test-method status="FAIL" signature="VerifyUrl()[pri:0, instance:Extent_Report.TestReport2@2833cc44]" name="VerifyUrl" duration-ms="5895" started-at="2018-01-10T17:28:53Z" finished-at="2018-01-10T17:28:58Z">
          <exception class="java.lang.AssertionError">
            <message>
              <![CDATA[expected [true] but found [false]]]>
            </message>
            <full-stacktrace>
              <![CDATA[java.lang.AssertionError: expected [true] but found [false]at org.testng.Assert.fail(Assert.java:96)at org.testng.Assert.failNotEquals(Assert.java:776)at org.testng.Assert.assertTrue(Assert.java:44)at org.testng.Assert.assertTrue(Assert.java:54)at Extent_Report.TestReport2.VerifyUrl(TestReport2.java:58)at sun.reflect.NativeMethodAccessorImpl.invoke0(Native Method)at sun.reflect.NativeMethodAccessorImpl.invoke(Unknown Source)at sun.reflect.DelegatingMethodAccessorImpl.invoke(Unknown Source)at java.lang.reflect.Method.invoke(Unknown Source)at org.testng.internal.MethodInvocationHelper.invokeMethod(MethodInvocationHelper.java:124)at org.testng.internal.Invoker.invokeMethod(Invoker.java:571)at org.testng.internal.Invoker.invokeTestMethod(Invoker.java:707)at org.testng.internal.Invoker.invokeTestMethods(Invoker.java:979)at org.testng.internal.TestMethodWorker.invokeTestMethods(TestMethodWorker.java:125)at org.testng.internal.TestMethodWorker.run(TestMethodWorker.java:109)at org.testng.TestRunner.privateRun(TestRunner.java:648)at org.testng.TestRunner.run(TestRunner.java:505)at org.testng.SuiteRunner.runTest(SuiteRunner.java:455)at org.testng.SuiteRunner.runSequentially(SuiteRunner.java:450)at org.testng.SuiteRunner.privateRun(SuiteRunner.java:415)at org.testng.SuiteRunner.run(SuiteRunner.java:364)at org.testng.SuiteRunnerWorker.runSuite(SuiteRunnerWorker.java:52)at org.testng.SuiteRunnerWorker.run(SuiteRunnerWorker.java:84)at org.testng.TestNG.runSuitesSequentially(TestNG.java:1187)at org.testng.TestNG.runSuitesLocally(TestNG.java:1116)at org.testng.TestNG.runSuites(TestNG.java:1028)at org.testng.TestNG.run(TestNG.java:996)at org.testng.remote.AbstractRemoteTestNG.run(AbstractRemoteTestNG.java:114)at org.testng.remote.RemoteTestNG.initAndRun(RemoteTestNG.java:251)at org.testng.remote.RemoteTestNG.main(RemoteTestNG.java:77)]]>
            </full-stacktrace>
          </exception> <!-- java.lang.AssertionError -->
          <reporter-output>
          </reporter-output>
        </test-method> <!-- VerifyUrl -->
        <test-method status="PASS" signature="tearDown(org.testng.ITestResult)[pri:0, instance:Extent_Report.TestReport2@2833cc44]" name="tearDown" is-config="true" duration-ms="9160" started-at="2018-01-10T17:28:58Z" finished-at="2018-01-10T17:29:08Z">
          <params>
            <param index="0">
              <value>
                <![CDATA[[TestResult name=VerifyUrl status=FAILURE method=TestReport2.VerifyUrl()[pri:0, instance:Extent_Report.TestReport2@2833cc44] output={null}]]]>
              </value>
            </param>
          </params>
          <reporter-output>
          </reporter-output>
        </test-method> <!-- tearDown -->
      </class> <!-- Extent_Report.TestReport2 -->
    </test> <!-- Default test -->
  </suite> <!-- Default suite -->
</testng-results>
